Workbook

Sheet Master
A1: List of Active Seamen
A3: (Semua Kapal) (Semua Rank)
A4: Dicetak pada 01/07/2025 07:44:44
A6: No. | B6: Seaman Code | C6: Seaman Name | D6: Rank | E6: Previous Vessel | F6: Vessel | G6: Fleet | H6: Crewing | I6: Transaction Date | J6: Masa Kerja | K6: Masa On Board | L6: Umur | M6: Key Certificate Name | N6: Key Cert. Number | O6: Key Cert. Exp | P6: Vaksin I | Q6: Vaksin II | R6: Vaksin III | S6: Vaksin IV | T6: AFF | U6: AFF Exp | V6: BST | W6: BST Exp | X6: PSCRB | Y6: PSCRB Exp | Z6: Buku Pelaut | AA6: Buku Pelaut Exp | AB6: MCU | AC6: MCU Exp | AD6: MEFA | AE6: SDSD | AF6: SSAT | AG6: SSO | AH6: RASD Cert. No | AI6: RASE Cert. No | AJ6: BRM Cert. No | AK6: RFE Cert. No | AL6: RASN Cert. No | AM6: Education | AN6: TLP
A7: 1 | B7: 20040312 | C7: HAMID HALIK | D7: NAKHODA | E7: PENDING CUTI | F7: BC. ANGSA LAUT | G7: F | H7: fenru samosir | I7: 45754 | J7: 4 tahun 4 bulan 7 hari | K7: 0 tahun 2 bulan 24 hari | L7: 58 tahun 9 bulan 22 hari | M7: ANT-IV | N7: 6200064037M40517 | O7: 46468 | P7: 44396 | Q7: 44427 | R7: 44646 | T7: 6200064037060522 | U7: 46441 | V7: 6200064037010522 | W7: 46441 | X7: 6200064037040522 | Y7: 46441 | Z7: J 074395 | AA7: 46698 | AB7: 6200064037MC7224 | AC7: 46150 | AD7: 6200064037070517 | AE7: - | AF7: 6200064037310516 | AG7: 6200064037240522 | AH7: - | AI7: - | AJ7: - | AK7: - | AL7: - | AM7: UMUM | AN7: 0318438184, 081520376816
A8: 2 | B8: 20100509 | C8: ARIF EFENDI | D8: MUALIM I | E8: PENDING CUTI | F8: BC. ANGSA LAUT | G8: F | H8: fenru samosir | I8: 45740 | J8: 2 tahun 3 bulan 22 hari | K8: 0 tahun 3 bulan 7 hari | L8: 34 tahun 3 bulan 7 hari | M8: ANT-III | N8: 6200397121N30321 | O8: 46341 | P8: 44386 | Q8: 44414 | R8: 44607 | T8: 6200397121060321 | U8: 46099 | V8: 6200397121012521 | W8: 46077 | X8: 6200397121042521 | Y8: 46077 | Z8: F 257540 | AA8: 46229 | AB8: 6200397121MC12324 | AC8: 46178 | AD8: 6200397121070321 | AE8: 6200397121320321 | AF8: 6200397121310321 | AG8: 6200397121240320 | AH8: - | AI8: - | AJ8: 6200397121230320 | AK8: - | AL8: - | AM8: SMA GROBONGAN | AN8: 08562726030
A9: 3 | B9: 20140031 | C9: MUHAMMAD ARIF | D9: KKM | E9: DARAT BIASA | F9: BC. ANGSA LAUT | G9: F | H9: fenru samosir | I9: 45808 | J9: 0 tahun 2 bulan 22 hari | K9: 0 tahun 1 bulan 1 hari | L9: 34 tahun 3 bulan 1 hari | M9: ATT-IV | N9: 6201112944S40218 | O9: 47525 | P9: 44328 | Q9: 44443 | R9: 44719 | T9: 6201112944060725 | U9: 47528 | V9: 6201112944010725 | W9: 47525 | X9: 6201112944040725 | Y9: 47533 | Z9: K 017712 | AA9: 46807 | AB9: 6201112944MC1025 | AC9: 46444 | AD9: 6201112944070225 | AE9: 6201112944320225 | AF9: 6201112944310225 | AG9: 6201112944240225 | AH9: - | AI9: - | AJ9: - | AK9: - | AL9: - | AM9: Diklat Poktepel | AN9: 085231551115, 082254548374
A10: 4 | B10: 20080470 | C10: BAMBANG WARDOYO | D10: MASINIS II | E10: BC. KAIMANA INDAH | F10: BC. ANGSA LAUT | G10: F | H10: fenru samosir | I10: 45827 | J10: 3 tahun 1 bulan 27 hari | K10: 0 tahun 0 bulan 12 hari | L10: 41 tahun 8 bulan 12 hari | M10: ATT-IV | N10: 6201027031T40524 | O10: 47441 | P10: 44347 | Q10: 44443 | R10: 44655 | T10: 6201027031060520 | U10: 45930 | V10: 6201027031010520 | W10: 45930 | X10: 6201027031040520 | Y10: 45930 | Z10: J 030146 | AA10: 46523 | AB10: 6201027031MC7223 | AC10: 46009 | AD10: 6201027031070516` | AE10: - | AF10: 6201027031310515 | AG10: 6201027031240523 | AH10: - | AI10: - | AJ10: - | AK10: - | AL10: - | AM10: SMK2 ISLAM | AN10: 081333998151
A11: 5 | B11: 20080133 | C11: IBRAHIM | D11: JURU MUDI | E11: PENDING CUTI | F11: BC. ANGSA LAUT | G11: F | H11: fenru samosir | I11: 45772 | J11: 6 tahun 8 bulan 23 hari | K11: 0 tahun 2 bulan 6 hari | L11: 41 tahun 3 bulan 28 hari | M11: ANT-D | N11: 6200196466340223 | O11: 46828 | P11: 44441 | Q11: 44483 | R11: 44664 | S11: 45000 | T11: 6200196466060521 | U11: 46352 | V11: 6200196466012421 | W11: 46124 | X11: 6200196466040521 | Y11: 46355 | Z11: G 020766 | AA11: 45916 | AB11: 6200196466MC7225 | AC11: 46379 | AD11: 6200196466070517 | AE11: 6200196466320517 | AF11: 6200196466310517 | AG11: - | AH11: 6200196466340223 | AI11: - | AJ11: - | AK11: - | AL11: - | AM11: DIKLAT BST | AN11: 087812124144
A12: 6 | B12: 20130776 | C12: SANDY IRAWAN | D12: JURU MUDI | E12: BC. TENYO MARU | F12: BC. ANGSA LAUT | G12: F | H12: fenru samosir | I12: 45796 | J12: 6 tahun 5 bulan 12 hari | K12: 0 tahun 1 bulan 12 hari | L12: 39 tahun 8 bulan 28 hari | M12: ANT-V | N12: 6201198724N50619 | O12: 47289 | P12: 44384 | Q12: 44554 | R12: 44646 | T12: 6201198724060622 | U12: 46570 | V12: 6201198724010621 | W12: 46131 | X12: 6201198724040622 | Y12: 46569 | Z12: F 168225 | AA12: 45906 | AB12: 6201198724MC6224 | AC12: 46329 | AD12: 6201198724070416 | AE12: 6201198724320416 | AF12: 6201198724310416 | AG12: - | AH12: - | AI12: - | AJ12: - | AK12: - | AL12: - | AM12: DIKLAT ANT-V | AN12: 082131432201
A13: 7 | B13: 20090394 | C13: ANAS AMINUDIN BASHURI | D13: JURU MINYAK | E13: TB. ALPHA | F13: BC. ANGSA LAUT | G13: F | H13: fenru samosir | I13: 45813 | J13: 16 tahun 0 bulan 21 hari | K13: 0 tahun 0 bulan 26 hari | L13: 50 tahun 11 bulan 20 hari | M13: ATT-D | N13: 6200511108420517 | O13: 46461 | P13: 44387 | Q13: 44415 | R13: 44658 | T13: 6200511108060522 | U13: 46418 | V13: 6200511108010522 | W13: 46418 | X13: 6200511108040522 | Y13: 46418 | Z13: J 009760 | AA13: 46416 | AB13: 6200511108MC7224 | AC13: 45983 | AD13: 6200511108070518 | AE13: 6200511108320517 | AF13: 6200511108310517 | AG13: - | AH13: - | AI13: 6200511108420517 | AJ13: - | AK13: - | AL13: - | AM13: umum | AN13: 081230988611
A14: 8 | B14: 20250112 | C14: MOH. YOGA PRATAMA | D14: JURU MINYAK | E14: BC. ANGSA LAUT | F14: BC. ANGSA LAUT | G14: F | H14: fenru samosir | I14: 45813 | J14: 0 tahun 0 bulan 26 hari | K14: 0 tahun 0 bulan 26 hari | L14: 20 tahun 3 bulan 25 hari | M14: ATT-D | N14: 6212130705350525 | O14: 47618 | T14: 6212130705060525 | U14: 47596 | V14: 6212130705015021 | W14: 46300 | X14: 6212130705040525 | Y14: 47599 | Z14: J 031037 | AA14: 46558 | AB14: 6212130705MC7225 | AC14: 46538 | AD14: - | AE14: 6212130705320525 | AF14: 6212130705310525 | AG14: - | AH14: - | AI14: - | AJ14: - | AK14: 6212130705350525 | AL14: - | AM14: SMKN Darul | AN14: 082140604027, 085708090120
A15: 9 | B15: 20120251 | C15: TEGUH SETYO WIBOWO | D15: NAKHODA | E15: PENDING CUTI | F15: BC. BALIKPAPAN RAYA | G15: F | H15: fenru samosir | I15: 45601 | J15: 6 tahun 1 bulan 25 hari | K15: 0 tahun 7 bulan 26 hari | L15: 50 tahun 1 bulan 21 hari | M15: ANT-III | N15: 6200039074M30519 | O15: 47276 | P15: 44383 | Q15: 44411 | R15: 44646 | T15: 6200039074060520 | U15: 45935 | V15: 6200039074010520 | W15: 45935 | X15: 6200039074040520 | Y15: 45935 | Z15: F 233893 | AA15: 46148 | AB15: 6200039074MC7224 | AC15: 46220 | AD15: 6200039074070515 | AE15: - | AF15: 6200039074310515 | AG15: 6200039074240517 | AH15: - | AI15: - | AJ15: 6200039074230515 | AK15: - | AL15: - | AM15: diklat ANT-III | AN15: 081330023151
A16: 10 | B16: 20040165 | C16: ROKHIM | D16: MUALIM I | E16: PENDING CUTI | F16: BC. BALIKPAPAN RAYA | G16: F | H16: fenru samosir | I16: 45574 | J16: 25 tahun 8 bulan 0 hari | K16: 0 tahun 8 bulan 22 hari | L16: 47 tahun 9 bulan 20 hari | M16: ANT-V | N16: 6201039713M50517 | O16: 46422 | P16: 44380 | Q16: 44426 | R16: 44651 | T16: 6201039713060520 | U16: 45945 | V16: 6201039713010320 | W16: 46009 | X16: 6201039713040520 | Y16: 45945 | Z16: G 020767 | AA16: 45916 | AB16: 6201039713MC7224 | AC16: 46113 | AD16: 6201039713070516 | AE16: - | AF16: 6201039713310515 | AG16: 6201039713240522 | AH16: - | AI16: - | AJ16: - | AK16: - | AL16: - | AM16: UMUM | AN16: 0353431032, 08121782011
A17: 11 | B17: 20170614 | C17: YOHANES ALUYSIUS PHILIPS OLA | D17: MUALIM II | E17: BC. BANJARMASIN RAYA | F17: BC. BALIKPAPAN RAYA | G17: F | H17: fenru samosir | I17: 45698 | J17: 4 tahun 1 bulan 11 hari | K17: 0 tahun 4 bulan 21 hari | L17: 31 tahun 1 bulan 2 hari | M17: ANT-III | N17: 6202088222M30523 | O17: 46951 | P17: 44393 | Q17: 44434 | R17: 44649 | T17: 6202088222060522 | U17: 46583 | V17: 6202088222010522 | W17: 46527 | X17: 6202088222040522 | Y17: 46404 | Z17: G 124331 | AA17: 46359 | AB17: 6202088222MC7224 | AC17: 46304 | AD17: 6202088222070517 | AE17: - | AF17: 6202088222310516 | AG17: 6202088222240521 | AH17: - | AI17: - | AJ17: 6202088222230517 | AK17: - | AL17: - | AM17: SPM Bhakti Samudera | AN17: 082244419220, 085172308080
A18: 12 | B18: 20050373 | C18: PURNOMO MARSUDI | D18: KKM | E18: PENDING CUTI | F18: BC. BALIKPAPAN RAYA | G18: F | H18: fenru samosir | I18: 45787 | J18: 9 tahun 1 bulan 29 hari | K18: 0 tahun 1 bulan 21 hari | L18: 50 tahun 0 bulan 7 hari | M18: ATT-III | N18: 6200503936S30516 | O18: 46198 | P18: 44410 | Q18: 44470 | R18: 44667 | T18: 6200503936060521 | U18: 46099 | V18: 6200503936010523 | W18: 46987 | X18: 6200503936040521 | Y18: 46099 | Z18: F 268448 | AA18: 46274 | AB18: 6200503936MC7224 | AC18: 46313 | AD18: 6200503936070514 | AE18: - | AF18: 6200503936310515 | AG18: 6200503936240521 | AH18: - | AI18: - | AJ18: - | AK18: - | AL18: - | AM18: BAKTI SAMUDERA | AN18: 0328667964
A19: 13 | B19: 20040705 | C19: MOH. HASAN FATONI | D19: MASINIS I | E19: PENDING CUTI | F19: BC. BALIKPAPAN RAYA | G19: F | H19: fenru samosir | I19: 45801 | J19: 29 tahun 2 bulan 22 hari | K19: 0 tahun 1 bulan 7 hari | L19: 54 tahun 2 bulan 19 hari | M19: ATT-V | N19: 6200072650S50516 | O19: 46250 | P19: 44393 | Q19: 44427 | R19: 44646 | S19: 45029 | T19: 6200072650060521 | U19: 46316 | V19: 6200072650010521 | W19: 46316 | X19: 6200072650040521 | Y19: 46316 | Z19: F 268381 | AA19: 46271 | AB19: 6200072650MC7224 | AC19: 46159 | AD19: 6200072650070516 | AE19: - | AF19: 6200072650310516 | AG19: 6200072650240523 | AH19: - | AI19: - | AJ19: - | AK19: - | AL19: - | AM19: UMUM | AN19: 0313094560
A20: 14 | B20: 20180247 | C20: BASUKI | D20: JURU MUDI | E20: DARAT BIASA | F20: BC. BALIKPAPAN RAYA | G20: F | H20: fenru samosir | I20: 45768 | J20: 1 tahun 6 bulan 13 hari | K20: 0 tahun 2 bulan 10 hari | L20: 31 tahun 1 bulan 3 hari | M20: ANT-D | N20: 6211753743340523 | O20: 46912 | P20: 44375 | Q20: 44420 | R20: 44786 | T20: 6211753743060523 | U20: 47084 | V20: 6211753743010522 | W20: 46637 | X20: 6211753743040523 | Y20: 47084 | Z20: J 074357 | AA20: 46694 | AB20: 6211753743MC7224 | AC20: 46065 | AD20: 6211753743070524 | AE20: 6211753743320524 | AF20: 6211753743310517 | AG20: - | AH20: 6211753743340523 | AI20: - | AJ20: - | AK20: - | AL20: - | AM20: SMA N MADIUN | AN20: 085733327523
A21: 15 | B21: 20240081 | C21: MUHAMMAD IQRAN | D21: JURU MUDI | E21: DARAT BIASA | F21: BC. BALIKPAPAN RAYA | G21: F | H21: fenru samosir | I21: 45829 | J21: 1 tahun 3 bulan 7 hari | K21: 0 tahun 0 bulan 10 hari | L21: 29 tahun 8 bulan 7 hari | M21: ANT-IV | N21: 6201407557N40624 | O21: 47171 | P21: 44394 | Q21: 44552 | R21: 44646 | T21: 6201407557060520 | U21: 45861 | V21: 6201407557010622 | W21: 46531 | X21: 6201407557042820 | Y21: 46028 | Z21: I 061580 | AA21: 46211 | AB21: 6201407557MC11025 | AC21: 46449 | AD21: 6201407557070623 | AE21: - | AF21: 6201407557310520 | AG21: 6201407557240624 | AH21: - | AI21: - | AJ21: - | AK21: - | AL21: - | AM21: SMK Katangka | AN21: 081245269528
A22: 16 | B22: 20090145 | C22: ABDU ROHMAN | D22: JURU MINYAK | E22: PENDING CUTI | F22: BC. BALIKPAPAN RAYA | G22: F | H22: fenru samosir | I22: 45787 | J22: 16 tahun 3 bulan 24 hari | K22: 0 tahun 1 bulan 21 hari | L22: 36 tahun 8 bulan 4 hari | M22: ATT-D | N22: 6200352816420517 | O22: 46454 | P22: 44396 | Q22: 44428 | R22: 44650 | T22: 6200352816060521 | U22: 46070 | V22: 6200352816010525 | W22: 47552 | X22: 6200352816040521 | Y22: 46070 | Z22: F 268565 | AA22: 46277 | AB22: 6200352816MC7224 | AC22: 46241 | AD22: 6200352816070523 | AE22: 6200352816320516 | AF22: 6200352816310516 | AG22: - | AH22: - | AI22: 6200352816420517 | AJ22: - | AK22: - | AL22: - | AM22: UMUM | AN22: 081234354282
A23: 17 | B23: 20180116 | C23: NOFERI | D23: JURU MINYAK | E23: PENDING CUTI | F23: BC. BALIKPAPAN RAYA | G23: F | H23: fenru samosir | I23: 45818 | J23: 7 tahun 3 bulan 11 hari | K23: 0 tahun 0 bulan 21 hari | L23: 31 tahun 3 bulan 16 hari | M23: ATT-D | N23: 6202193310420518 | O23: 46802 | P23: 44380 | Q23: 44417 | R23: 44646 | T23: 6202193310060520 | U23: 46005 | V23: 6202193310010524 | W23: 47309 | X23: 6202193310040520 | Y23: 45991 | Z23: F 245046 | AA23: 46199 | AB23: RSD TIMIKA | AC23: 46159 | AD23: 6202193310070523 | AE23: 6202193310320523 | AF23: 6202193310310515 | AG23: - | AH23: - | AI23: 6202193310420518 | AJ23: - | AK23: - | AL23: - | AM23: DIKLAT ATT-D | AN23: 082225221593
A24: 18 | B24: 20050274 | C24: DANIEL LAHUANG | D24: NAKHODA | E24: PENDING CUTI | F24: BC. BANJARMASIN RAYA | G24: F | H24: fenru samosir | I24: 45801 | J24: 38 tahun 2 bulan 16 hari | K24: 0 tahun 1 bulan 7 hari | L24: 62 tahun 1 bulan 3 hari | M24: ANT-IV | N24: 6200122485M40617 | O24: 46602 | P24: 44380 | Q24: 44417 | R24: 44634 | S24: 45026 | T24: 6200122485060421 | U24: 46100 | V24: 6200122485010421 | W24: 46100 | X24: 6200122485040421 | Y24: 46100 | Z24: F 026423 | AA24: 45805 | AB24: 6200122485MC5424 | AC24: 46156 | AD24: 6200122485070416 | AE24: - | AF24: 6200122485310417 | AG24: 6200122485240417 | AH24: - | AI24: - | AJ24: 6200122485230417 | AK24: - | AL24: - | AM24: UMUM | AN24: 0317457232
A25: 19 | B25: 20190265 | C25: SILFAN | D25: MUALIM II | E25: PENDING CUTI | F25: BC. BANJARMASIN RAYA | G25: F | H25: fenru samosir | I25: 45768 | J25: 1 tahun 3 bulan 8 hari | K25: 0 tahun 2 bulan 10 hari | L25: 31 tahun 5 bulan 21 hari | M25: ANT-III | N25: 6201353160010121 | O25: 46324 | P25: 44244 | Q25: 44370 | R25: 44626 | T25: 6201353160060121 | U25: 46324 | V25: 6201353160010121 | W25: 46324 | X25: 6201353160040121 | Y25: 46324 | Z25: J 018277 | AA25: 46460 | AB25: 6201353160MC5424 | AC25: 46059 | AD25: 6201353160070116 | AE25: 6201353160320116 | AF25: 6201353160310116 | AG25: 6201353160240419 | AH25: - | AI25: - | AJ25: 6201353160230418 | AK25: - | AL25: - | AM25: SMK Pelayaran | AN25: 081342903175
A26: 20 | B26: 20220371 | C26: AAN KHAYUN ASNGADI | D26: MASINIS I | E26: DARAT BIASA | F26: BC. BANJARMASIN RAYA | G26: F | H26: fenru samosir | I26: 45757 | J26: 2 tahun 6 bulan 4 hari | K26: 0 tahun 2 bulan 21 hari | L26: 33 tahun 1 bulan 6 hari | M26: ATT-IV | N26: 6200386029T40221 | O26: 46288 | P26: 44396 | Q26: 44424 | R26: 44646 | T26: 6200386029060321 | U26: 46119 | V26: 6200386029010322 | W26: 46552 | X26: 6200386029040321 | Y26: 46119 | Z26: F 231272 | AA26: 45840 | AB26: 6200386029MC9225 | AC26: 46456 | AD26: 6200386029070222 | AE26: 6200386029320222 | AF26: 6200386029310222 | AG26: - | AH26: - | AI26: 6200386029420222 | AJ26: - | AK26: - | AL26: - | AM26: SMK N 1 PURING | AN26: 081326267760, 6281296163356
A27: 21 | B27: 20040174 | C27: FREDERICK NINGKA TANGKUDUNG | D27: SERANG | E27: PENDING CUTI | F27: BC. BANJARMASIN RAYA | G27: F | H27: fenru samosir | I27: 45574 | J27: 24 tahun 1 bulan 27 hari | K27: 0 tahun 8 bulan 22 hari | L27: 65 tahun 3 bulan 29 hari | M27: ANT-D | N27: 6201005651340517 | O27: 46461 | P27: 44392 | Q27: 44426 | R27: 44706 | T27: 6201005651061124 | U27: 47339 | V27: 6201005651011124 | W27: 47339 | X27: 6201005651041124 | Y27: 47344 | Z27: F 287526 | AA27: 46329 | AB27: 6201005651MC7224 | AC27: 46229 | AD27: 6201005651070715 | AE27: 6201005651320517 | AF27: 6201005651310715 | AG27: - | AH27: 6201005651340517 | AI27: - | AJ27: - | AK27: - | AL27: - | AM27: UMUM | AN27: 08165456864
A28: 22 | B28: 20140532 | C28: MOH. DARTO | D28: JURU MUDI | E28: PENDING CUTI | F28: BC. BANJARMASIN RAYA | G28: F | H28: fenru samosir | I28: 45724 | J28: 9 tahun 8 bulan 28 hari | K28: 0 tahun 3 bulan 23 hari | L28: 34 tahun 2 bulan 16 hari | M28: ANT-V | N28: 6200361767N50514 | O28: 45875 | P28: 44411 | Q28: 44435 | R28: 44737 | T28: 6200361767060523 | U28: 47098 | V28: 6200361767010522 | W28: 46639 | X28: 6200361767040523 | Y28: 47098 | Z28: I 042161 | AA28: 46172 | AB28: 6200361767MC7224 | AC28: 46206 | AD28: 6200361767070513 | AE28: 6200361767320518 | AF28: 6200361767310514 | AG28: 6200361767240523 | AH28: - | AI28: - | AJ28: - | AK28: - | AL28: - | AM28: umum | AN28: 081335355565
A29: 23 | B29: 20190296 | C29: AHMAD FAUZI | D29: JURU MINYAK | E29: DARAT BIASA | F29: BC. BANJARMASIN RAYA | G29: F | H29: fenru samosir | I29: 45661 | J29: 3 tahun 0 bulan 13 hari | K29: 0 tahun 5 bulan 27 hari | L29: 30 tahun 8 bulan 15 hari | M29: ATT-D | N29: 6211416027420522 | O29: 45977 | P29: 44392 | Q29: 44460 | R29: 44652 | T29: 6211416027060520 | U29: 45936 | V29: 6211416027010524 | W29: 47294 | X29: 6211416027040521 | Y29: 46034 | Z29: G 123569 | AA29: 46327 | AB29: 6211416027MC7224 | AC29: 45989 | AD29: 6211416027070514 | AE29: 6211416027320114 | AF29: 6211416027310114 | AG29: - | AH29: - | AI29: 6201005651340517 | AJ29: - | AK29: - | AL29: - | AM29: SMA Bangkalan | AN29: 085354016966
A30: 24 | B30: 20240196 | C30: RENDI OKI ALFIANSYAH | D30: JURU MINYAK | E30: BC. BANJARMASIN RAYA | F30: BC. BANJARMASIN RAYA | G30: F | H30: fenru samosir | I30: 45503 | J30: 0 tahun 11 bulan 1 hari | K30: 0 tahun 11 bulan 1 hari | L30: 24 tahun 0 bulan 0 hari | M30: ATT-D | N30: 6212110321420524 | O30: 47149 | P30: 44282 | Q30: 44433 | R30: 44769 | T30: 6212110321060521 | U30: 46147 | V30: 6212110321010521 | W30: 46126 | X30: 6212110321040522 | Y30: 46611 | Z30: G 085115 | AA30: 46166 | AB30: 6212110321MC7224 | AC30: 46184 | AD30: 6212110321070524 | AE30: 6212110321320524 | AF30: 6212110321310521 | AG30: - | AH30: - | AI30: 6212110321420524 | AJ30: - | AK30: - | AL30: - | AM30: SMK PGRI 6 | AN30: 082141168744
A31: 25 | B31: 20070155 | C31: ADI PURWANTO | D31: NAKHODA | E31: PENDING CUTI | F31: BC. BAYA | G31: F | H31: fenru samosir | I31: 45682 | J31: 5 tahun 10 bulan 25 hari | K31: 0 tahun 5 bulan 6 hari | L31: 40 tahun 1 bulan 12 hari | M31: ANT-III | N31: 6200204861M30123 | O31: 46968 | P31: 44411 | Q31: 44554 | R31: 44644 | T31: 6200204861060521 | U31: 46322 | V31: 6200204861010525 | W31: 47589 | X31: 6200204861040525 | Y31: 47589 | Z31: J 030928 | AA31: 46552 | AB31: 6200204861MC7225 | AC31: 46491 | AD31: 6200204861070515 | AE31: - | AF31: 6200204861310516 | AG31: 6200204861240522 | AH31: - | AI31: - | AJ31: 6200204861230516 | AK31: - | AL31: - | AM31: DIKLAT ANT-IV | AN31: 03160440010, 03160440010, 085347728866
A32: 26 | B32: 20050291 | C32: PURWANTO | D32: MUALIM I | E32: PENDING CUTI | F32: BC. BAYA | G32: F | H32: fenru samosir | I32: 45725 | J32: 11 tahun 0 bulan 19 hari | K32: 0 tahun 3 bulan 22 hari | L32: 51 tahun 11 bulan 15 hari | M32: ANT-V | N32: 6200360222M50517 | O32: 46378 | P32: 44434 | Q32: 44485 | R32: 44665 | T32: 6200360222060520 | U32: 45859 | V32: 6200360222010520 | W32: 45848 | X32: 6200360222040520 | Y32: 45859 | Z32: F 222280 | AA32: 46127 | AB32: 6200360222MC7224 | AC32: 46267 | AD32: 6200360222070511 | AE32: - | AF32: 6200360222310516 | AG32: 6200360222240522 | AH32: - | AI32: - | AJ32: - | AK32: - | AL32: - | AM32: UMUM | AN32: 081335627908
A33: 27 | B33: 20130927 | C33: ARIS AMBORO | D33: MUALIM II | E33: PENDING CUTI | F33: BC. BAYA | G33: F | H33: fenru samosir | I33: 45621 | J33: 8 tahun 9 bulan 22 hari | K33: 0 tahun 7 bulan 6 hari | L33: 34 tahun 2 bulan 21 hari | M33: ANT-IV | N33: 6201576699N40524 | O33: 47384 | P33: 44381 | Q33: 44412 | R33: 44616 | T33: 6201576699060522 | U33: 46394 | V33: 6201576699010522 | W33: 46394 | X33: 6201576699040522 | Y33: 46394 | Z33: K 002455 | AA33: 46748 | AB33: 6201576699MC7223 | AC33: 45927 | AD33: 6201576699070517 | AE33: 6201576699320516 | AF33: 6201576699310515 | AG33: 6201576699240524 | AH33: - | AI33: - | AJ33: - | AK33: - | AL33: - | AM33: UMUM | AN33: 085752595651
A34: 28 | B34: 20050306 | C34: AGUS TRIYANA | D34: KKM | E34: PENDING CUTI | F34: BC. BAYA | G34: F | H34: fenru samosir | I34: 45537 | J34: 31 tahun 9 bulan 2 hari | K34: 0 tahun 9 bulan 29 hari | L34: 55 tahun 10 bulan 3 hari | M34: ATT-IV | N34: 6200125380S40317 | O34: 46372 | P34: 44434 | Q34: 44477 | R34: 44741 | S34: 45176 | T34: 6200125380060321 | U34: 46357 | V34: 6200125380010321 | W34: 46358 | X34: 6200125380040321 | Y34: 46356 | Z34: F 234559 | AA34: 46171 | AB34: 6200125380MC0124 | AC34: 46207 | AD34: 6200125380070316 | AE34: - | AF34: 6200125380310315 | AG34: 6200125380240315 | AH34: - | AI34: - | AJ34: - | AK34: - | AL34: - | AM34: UMUM | AN34: 081216217512
A35: 29 | B35: 20120203 | C35: BAMBANG BUDI PURWANTO | D35: MASINIS I | E35: DARAT BIASA | F35: BC. BAYA | G35: F | H35: fenru samosir | I35: 45559 | J35: 1 tahun 4 bulan 4 hari | K35: 0 tahun 9 bulan 7 hari | L35: 49 tahun 1 bulan 1 hari | M35: ATT-III | N35: 6200499982C30317 | O35: 46554 | P35: 44414 | Q35: 44515 | R35: 44617 | T35: 6200499982060320 | U35: 45911 | V35: 6200499982010320 | W35: 45911 | X35: 6200499982040320 | Y35: 45911 | Z35: J 088818 | AA35: 46662 | AB35: 6200499982MC7224 | AC35: 46051 | AD35: 6200499982070310 | AE35: - | AF35: 6200499982310516 | AG35: - | AH35: - | AI35: - | AJ35: - | AK35: - | AL35: - | AM35: AMI Medan | AN35: 081230530366
A36: 30 | B36: 20040581 | C36: SUMARTONO | D36: MASINIS II | E36: PENDING CUTI | F36: BC. BAYA | G36: F | H36: fenru samosir | I36: 45787 | J36: 21 tahun 0 bulan 16 hari | K36: 0 tahun 1 bulan 21 hari | L36: 55 tahun 2 bulan 20 hari | M36: ATT-V | N36: 6200419366S50516 | O36: 46477 | P36: 44392 | Q36: 44420 | R36: 44632 | T36: 6200419366060520 | U36: 45854 | V36: 6200419366010520 | W36: 45854 | X36: 6200419366040520 | Y36: 45854 | Z36: F 222268 | AA36: 46127 | AB36: 6200419366MC7224 | AC36: 46144 | AD36: 6200419366070515 | AE36: - | AF36: 6200419366310515 | AG36: 6200419366240522 | AH36: - | AI36: - | AJ36: - | AK36: - | AL36: - | AM36: UMUM | AN36: 081332145001, 081332145001
A37: 31 | B37: 20110689 | C37: RAMBLI WAWORUNTU | D37: JURU MUDI | E37: TB. SPIL BOAT | F37: BC. BAYA | G37: F | H37: fenru samosir | I37: 45766 | J37: 11 tahun 1 bulan 23 hari | K37: 0 tahun 2 bulan 12 hari | L37: 32 tahun 0 bulan 7 hari | M37: ANT-D | N37: 6201563386340519 | O37: 47325 | P37: 44393 | Q37: 44462 | R37: 44634 | T37: 6201563386060522 | U37: 46462 | V37: 6201563386010522 | W37: 46463 | X37: 6201563386040524 | Y37: 47447 | Z37: F 222281 | AA37: 46136 | AB37: 6201563386MC7224 | AC37: 46145 | AD37: - | AE37: 6201563386320517 | AF37: 6201563386310517 | AG37: - | AH37: 6201563386340519 | AI37: - | AJ37: - | AK37: - | AL37: - | AM37: UMUM | AN37: 081358580224, 081330965863
A38: 32 | B38: 20070260 | C38: SURATNO | D38: JURU MINYAK | E38: PENDING CUTI | F38: BC. BAYA | G38: F | H38: fenru samosir | I38: 45724 | J38: 18 tahun 1 bulan 1 hari | K38: 0 tahun 3 bulan 23 hari | L38: 46 tahun 11 bulan 8 hari | M38: ATT-D | N38: 6201040638420517 | O38: 46427 | P38: 44463 | Q38: 44496 | R38: 44749 | T38: 6201040638060521 | U38: 46378 | V38: 6201040638010521 | W38: 46378 | X38: 6201040638040521 | Y38: 46378 | Z38: F 222279 | AA38: 46127 | AB38: 6201040638MC7225 | AC38: 46378 | AD38: 6201040638070522 | AE38: 6201040638320516 | AF38: 6201040638310516 | AG38: - | AH38: - | AI38: 6201040638420517 | AJ38: - | AK38: - | AL38: - | AM38: UMUM | AN38: 0813482369926
A39: 33 | B39: 20040180 | C39: M. ASY'ARI AFANDI | D39: NAKHODA | E39: PENDING CUTI | F39: BC. BELAWAN RAYA | G39: F | H39: fenru samosir | I39: 45824 | J39: 4 tahun 1 bulan 5 hari | K39: 0 tahun 0 bulan 15 hari | L39: 50 tahun 0 bulan 24 hari | M39: ANT-III | N39: 6200120046N30521 | O39: 46163 | P39: 44392 | Q39: 44428 | R39: 44671 | T39: 6200120046060520 | U39: 45911 | V39: 6200120046010524 | W39: 47164 | X39: 6200120046040520 | Y39: 45911 | Z39: F 288252 | AA39: 45968 | AB39: 6200120046MC7224 | AC39: 46299 | AD39: 6200120046070515 | AE39: - | AF39: 6200120046310515 | AG39: 6200120046240521 | AH39: - | AI39: - | AJ39: - | AK39: - | AL39: - | AM39: SPM PELAYARAN | AN39: 082131115530, 081247704115
A40: 34 | B40: 20180365 | C40: SAIPUL SIHOMBING | D40: MUALIM I | E40: BC. KAIMANA INDAH | F40: BC. BELAWAN RAYA | G40: F | H40: fenru samosir | I40: 45599 | J40: 6 tahun 10 bulan 22 hari | K40: 0 tahun 7 bulan 28 hari | L40: 32 tahun 6 bulan 1 hari | M40: ANT-IV | N40: 6201472900N40518 | O40: 46836 | P40: 44365 | Q40: 44392 | R40: 44642 | T40: 6201472900060521 | U40: 46175 | V40: 6201472900010523 | W40: 46836 | X40: 6201472900040523 | Y40: 46836 | Z40: F 343367 | AA40: 45774 | AB40: 6201472900MC6224 | AC40: 46069 | AD40: 6201472900070518 | AE40: - | AF40: - | AG40: 6201472900240517 | AH40: - | AI40: - | AJ40: 6201472900230517 | AK40: - | AL40: - | AM40: DIKLAT ANT -IV | AN40: 081311674347, 085852817081
A41: 35 | B41: 20170547 | C41: HERU HARNOWO | D41: MUALIM II | E41: BC. BELAWAN RAYA | F41: BC. BELAWAN RAYA | G41: F | H41: fenru samosir | I41: 45670 | J41: 7 tahun 7 bulan 9 hari | K41: 0 tahun 5 bulan 18 hari | L41: 31 tahun 10 bulan 1 hari | M41: ANT-V | N41: 6201098609N50518 | O41: 46828 | P41: 44389 | Q41: 44554 | R41: 44644 | T41: 6201098609060522 | U41: 46467 | V41: 6201098609010522 | W41: 46467 | X41: 6201098609040522 | Y41: 46467 | Z41: J 051861 | AA41: 46635 | AB41: 6201098609MC7224 | AC41: 46374 | AD41: 6201098609070517 | AE41: 6201098609320517 | AF41: 6201098609310517 | AG41: 6201098609240523 | AH41: - | AI41: - | AJ41: - | AK41: - | AL41: - | AM41: DIKLAT ANT-D | AN41: 081330463099
A42: 36 | B42: 20050201 | C42: MURSALIM | D42: KKM | E42: PENDING CUTI | F42: BC. BELAWAN RAYA | G42: F | H42: fenru samosir | I42: 45574 | J42: 6 tahun 11 bulan 20 hari | K42: 0 tahun 8 bulan 22 hari | L42: 49 tahun 9 bulan 7 hari | M42: ATT-IV | N42: 6201027303S40517 | O42: 46335 | P42: 44380 | Q42: 44417 | R42: 44615 | T42: 6201027303060520 | U42: 45872 | V42: 6201027303010520 | W42: 45872 | X42: 6201027303040520 | Y42: 45872 | Z42: F 106950 | AA42: 45807 | AB42: 6201027303MC7225 | AC42: 46403 | AD42: 6201027303070515 | AE42: - | AF42: 6201027303310516 | AG42: 6201027303240523 | AH42: - | AI42: - | AJ42: - | AK42: - | AL42: - | AM42: diklat ATT-IV | AN42: bimanovalliansy, 082254744957
...

Sheet Resume
B1: PROGRESS KONDITE CREW
B2: Periode Jan – Jun 2025
A3: NO | B3: Vessel Name | C3: CODE | D3: Crewing | E3: Received Hard Copy | G3: INPUT | I3: Di FILE | J3: Status | K3: KET
E4: Date | F4: Status | G4: DECK | H4: ENG
A5: 1 | B5: KM. MANALAGI WANDA | C5: MWA | D5: M Rizqi | F5: ok
A6: 2 | B6: KM. MANALAGI HITA | C6: MHI | D6: M Rizqi | F6: ok | K6: wa
A7: 3 | B7: KM. MANALAGI SAMBA | C7: MSM | D7: M Rizqi | F7: ok
A8: 4 | B8: KM. MANALAGI TISYA | C8: MTI | D8: M Rizqi | F8: ok
A9: 5 | B9: KM. MANALAGI YASA | C9: MYA | D9: M Rizqi | F9: ok
A10: 6 | B10: KM. MANALAGI TARA | C10: MAR | D10: M Rizqi | F10: ok
A11: 7 | B11: KM. MANALAGI VIRA | C11: MVI | D11: M Rizqi | F11: ok
A12: 8 | B12: KM. MANALAGI ENZI | C12: MEN | D12: M Rizqi | F12: ok
A13: 9 | B13: KM. MANALAGI PRITA | C13: MPR | D13: M Rizqi | F13: ok | K13: by wa
A14: 10 | B14: KM. MANALAGI ASTA | C14: MAA | D14: M Rizqi | F14: ok
A15: 11 | B15: KM. MANALAGI ASTI | C15: MIA | D15: M Rizqi | F15: ok
A16: 12 | B16: KM. MANALAGI DASA | C16: MDA | D16: M Rizqi | F16: ok
A17: 13 | B17: KM. XYS SATU | C17: XSA | D17: M Rizqi | F17: ok
A18: 14 | B18: KM. ORIENTAL DIAMOND | C18: ODI | D18: Jefri S | F18: ok
A19: 15 | B19: KM. ORIENTAL JADE | C19: OJA | D19: Jefri S | F19: ok
A20: 16 | B20: KM. ORIENTAL RUBY | C20: ORU | D20: Jefri S | F20: ok
A21: 17 | B21: KM. ORIENTAL GALAXY | C21: OGA | D21: Syahril G | F21: ok
A22: 18 | B22: KM. HIJAU SAMUDRA | C22: HSA | D22: Syahril G | F22: ok
A23: 19 | B23: KM. ORIENTAL GOLD | C23: OGO | D23: Syahril G | F23: ok
A24: 20 | B24: KM. ORIENTAL SILVER | C24: OSI | D24: Fenru S | F24: ok
A25: 21 | B25: KM. ORIENTAL EMERALD | C25: OEM | D25: Fenru S | F25: ok
... A30: 26 | B30: KM. SPIL HAYU | C30: HAY | D30: Jefri S | F30: ok
A31: 27 | B31: KM. SPIL HASYA | C31: HAS | D31: Jefri S | F31: ok | K31: wa
A32: 28 | B32: KM. SPIL HAPSRI | C32: HAP | D32: Jefri S | F32: ok | K32: wa
A33: 29 | B33: KM. SPIL HANA | C33: HAN | D33: Jefri S | F33: ok
A34: 30 | B34: KM. SPIL RATNA | C34: RAT | D34: Jefri S
A35: 31 | B35: KM. SPIL RUMI | C35: RUM | D35: Jefri S | F35: ok
A36: 32 | B36: KM. SPIL RENATA | C36: REN | D36: Jefri S | F36: ok
A37: 33 | B37: KM. SPIL RAHAYU | C37: RAH | D37: Jefri S | F37: ok
A38: 34 | B38: KM. SPIL RETNO | C38: RET | D38: Jefri S | F38: ok
A39: 35 | B39: KM. HIJAU SEJUK | C39: HSJ | D39: Fenru S | F39: ok
A40: 36 | B40: KM. HIJAU SEGAR | C40: HSG | D40: Syahril G | F40: ok
A41: 37 | B41: KM. PULAU NUNUKAN | C41: PNN | D41: Syahril G | F41: ok
A42: 38 | B42: KM. PULAU LAYANG | C42: PLA | D42: Syahril G | F42: ok
A43: 39 | B43: KM. PULAU WETAR | C43: PWE | D43: Syahril G | F43: ok
A44: 40 | B44: KM. PULAU HOKI | C44: PHK | D44: Syahril G | F44: ok
...

Sheet Kondite_Nakhoda_KKM_KM
A1: Kondite
A2: Periode Jan – Jun 2025
A4: NO | B4: Vessel Name | C4: Vessel Code | D4: Crewing | E4: Manager Nautik | F4: Manager Teknik | G4: Fleet | H4: SEAMAN CODE | I4: NAMA | J4: JABATAN | K4: Key Certificate | L4: Masa On Board | M4: Profil Pribadi | Z4: Profesionalitas | AM4: AVERAGE | AN4: RESULT | AO4: NOTE MN (ACCIDENT) | AP4: NAMA KURSUS
M5: Tingkah laku | P5: Sikap | S5: KPP | V5: Kepemimpinan | Z5: 1 | AA5: 2 | AB5: 3 | AC5: 4 | AD5: 5 | AE5: 6 | AF5: 7 | AG5: 8 | AH5: 9 | AI5: 10 | AJ5: 11 | AK5: 12 | AL5: 13 | AP5: SMK (1) | AQ5: GRAFIK NAVIGASI & KOREKSI PUBLIK (2) | AR5: KESESUAIAN MARPOL (3) | AS5: OPERASIONAL EFISIENSI PERMESINAN LAUT (4) | AT5: SISTEM MANUVER ME (5) | AU5: PELATIHAN KESELAMATAN RATING (6) | AV5: LATIHAN HIDROLIK (7) | AW5: PRAKTEK KELISTRIKAN (8) | AX5: MANAJEMEN SUMBER DAYA BRIDGE (9) | AY5: ANALISIS MENDASAR (10) | AZ5: PERWIRA KESELAMATAN KAPAL (11) | BA5: OTOMATISASI DAN KONTROL (12) | BB5: TEORI & PRAKTEK PENANGANAN KAPAL (13) | BC5: KEPEMIMPINAN (14) | BD5: MEMASUKI RUANG TERTUTUP (15)
M6: TNG | N6: SRG | O6: INT | P6: LOY | Q6: ATT | R6: KK | S6: KBL | T6: KMI | U6: MIL | V6: KMM | W6: KBT | X6: KMAK | Y6: KMK
B7: KM. AKASHIA | H7: 20170526 | I7: BOBBY BLESSY PANGALILA | J7: NAKHODA | L7: 0 tahun 4 bulan 4 hari
B8: KM. AKASHIA | H8: 20040203 | I8: MASWANTO | J8: KKM | L8: 1 tahun 1 bulan 2 hari
B9: KM. AKASHIA | H9: 20140337 | I9: KHOIRUL ANWAR | J9: EXTRA KKM | L9: 0 tahun 0 bulan 9 hari
B10: KM. ARMADA PERMATA | H10: 20100106 | I10: PETRUS ANDRONIKUS DUAN | J10: NAKHODA | L10: 0 tahun 5 bulan 17 hari
B11: KM. ARMADA PERMATA | H11: 20190234 | I11: EFRIWAN Z ABIDIN | J11: KKM | L11: 0 tahun 9 bulan 13 hari
B12: KM. ARMADA SEGARA | H12: 20190451 | I12: IRIYANTO | J12: NAKHODA | L12: 0 tahun 2 bulan 16 hari
B13: KM. ARMADA SEGARA | I13: R. DHANIE | J13: NAKHODA
B14: KM. ARMADA SEGARA | H14: 20050667 | I14: MUCH. MUCHLIS | J14: KKM | L14: 0 tahun 10 bulan 15 hari
B15: KM. ARMADA SENADA | H15: 20190390 | I15: ROBERT SIMANJUNTAK | J15: NAKHODA | L15: 0 tahun 6 bulan 12 hari
B16: KM. ARMADA SENADA | H16: 20040361 | I16: BUDIYONO | J16: KKM | L16: 0 tahun 5 bulan 27 hari
B17: KM. ARMADA SERASI | H17: 20121009 | I17: DEMAR MANURUNG | J17: NAKHODA | L17: 0 tahun 1 bulan 26 hari
B18: KM. ARMADA SERASI | H18: 20140034 | I18: I KOMANG ALIT KARIASA | J18: NAKHODA
B19: KM. ARMADA SERASI | H19: 20070443 | I19: MURSITO | J19: KKM | L19: 0 tahun 7 bulan 18 hari
B20: KM. BALI AYU | H20: 20220139 | I20: MEIZERIKO PATTIPEILOHY | J20: NAKHODA | L20: 0 tahun 5 bulan 6 hari
B21: KM. BALI AYU | H21: 20080530 | I21: YUSNAIDI | J21: KKM | L21: 0 tahun 0 bulan 7 hari
B22: KM. BALI AYU | H22: 20200012 | I22: SUPRIYANTO | J22: KKM
B23: KM. BALI GIANYAR | H23: 20090641 | I23: BAMBANG SUFRIYANTO | J23: NAKHODA | L23: 0 tahun 4 bulan 6 hari
B24: KM. BALI GIANYAR | H24: 20040256 | I24: ROFIQ ANANTA | J24: KKM | L24: 0 tahun 2 bulan 4 hari
B25: KM. BALI GIANYAR | H25: 20040213 | I25: DOMINICUS FITRIANUS DA SILVA | J25: KKM
B26: KM. BALI KUTA | H26: 20150590 | I26: SIGIT SUMANTO | J26: NAKHODA | L26: 0 tahun 1 bulan 4 hari
B27: KM. BALI KUTA | H27: 20080303 | I27: ASEP ATIK MASTRIS | J27: NAKHODA
B28: KM. BALI KUTA | H28: 20210226 | I28: SYAHIR | J28: KKM | L28: 0 tahun 7 bulan 29 hari
B29: KM. BALI SANUR | H29: 20240279 | I29: SAPTONO WAHYU WIBOWO | J29: NAKHODA | L29: 0 tahun 2 bulan 1 hari
B30: KM. BALI SANUR | H30: 20230137 | I30: KUSTOPO | J30: NAKHODA
B31: KM. BALI SANUR | H31: 20111027 | I31: BINTON SILALAHI | J31: KKM | L31: 0 tahun 2 bulan 1 hari
B32: KM. BALI SANUR | H32: 20121174 | I32: STEFANUS LILIWANA | J32: KKM
B33: KM. DERAJAT | H33: 20090419 | I33: SUPRIYADI | J33: NAKHODA | L33: 0 tahun 0 bulan 1 hari
B34: KM. DERAJAT | H34: 20160469 | I34: M. SUJONO | J34: KKM | L34: 0 tahun 0 bulan 19 hari
B35: KM. DERAJAT | H35: 20070251 | I35: AGUS CAHYO PRIANDIK | J35: KKM
B36: KM. FORTUNE | H36: 20080044 | I36: MAMAT MIHARJA | J36: NAKHODA | L36: 0 tahun 0 bulan 2 hari
B37: KM. FORTUNE | H37: 20070307 | I37: ANDREAS SURJANTO | J37: KKM | L37: 0 tahun 0 bulan 1 hari
B38: KM. HIJAU JELITA | H38: 20180263 | I38: MARSAID TEGUH SANTOSO | J38: NAKHODA | L38: 0 tahun 6 bulan 22 hari
B39: KM. HIJAU JELITA | H39: 20160274 | I39: KHAIRUL ANUWAR | J39: KKM | L39: 0 tahun 1 bulan 18 hari
B40: KM. HIJAU JELITA | H40: 20150195 | I40: JAFRISAL | J40: KKM
B41: KM. HIJAU SAMUDRA | H41: 20040054 | I41: OFTAVIANI PALIT | J41: NAKHODA | L41: 0 tahun 2 bulan 29 hari
...

Sheet All_Crew_Kondite_KM
A1: Kondite
A2: Periode Januari – Juni 2025
A4: NO | B4: Vessel Name | C4: Vessel Code | D4: Crewing | E4: Manager Nautik | F4: Manager Teknik | G4: Fleet | H4: SEAMAN CODE | I4: NAMA | J4: JABATAN | K4: Key Certificate | L4: Masa On Board | M4: MUALIM I & MASINIS I | AN4: AVERAGE | AO4: NAMA KURSUS | BD4: PERWIRA JUNIOR | CF4: AVERAGE | CG4: NAMA KURSUS | CV4: RATING | DO4: AVERAGE | DP4: NAMA KURSUS | EF4: Kategorisasi Condite
BD5: Profil Pribadi | BS5: Profesionalitas | CV5: Profil Pribadi | DI5: Profesionalitas
M6: TL | P6: Sikap | S6: Nilai & Nalar | V6: Kepemimpinan | Z6: 1 | AA6: 2 | AB6: 3 | AC6: 4 | AD6: 5 | AE6: 6 | AF6: 7 | AG6: 8 | AH6: 9 | AI6: 10 | AJ6: 11 | AK6: 12 | AL6: 13 | AM6: 14 | AO6: SMK (1) | AP6: GRAFIK NAVIGASI (2) | AQ6: KESESUAIAN MARPOL (3) | AR6: OPERASIONAL EFISIEN PERMESINAN LAUT (4) | AS6: SISTEM MANUVER ME (5) | AT6: PELATIHAN KESELAMATAN RATING (6) | AU6: LATIHAN SISTEM PERALATAN HIDROLIK (7) | AV6: PRAKTEK KELISTRIKAN (8) | AW6: MANAJEMEN SUMBER DAYA ANJUNGAN (9) | AX6: ANALISIS MENDASAR (10) | AY6: PERWIRA KESELAMATAN KAPAL (11) | AZ6: OTOMATISASI DAN KONTROL (12) | BA6: TEORI PRAKTEK PENANGANAN KAPAL (13) | BB6: KEPEMIMPINAN (14) | BC6: MEMASUKI RUANG TERTUTUP (15) | BD6: Tingkah laku & Sikap | BK6: Kemamp. Menilai N | BO6: Kepemimpinan | BS6: 1 | BT6: 2 | BU6: 3 | BV6: 4 | BW6: 5 | BX6: 6 | BY6: 7 | BZ6: 8 | CA6: 9 | CB6: 10 | CC6: 11 | CD6: 12 | CE6: 13 | CG6: SMK (1) | CH6: GRAFIK NAVIGASI (2) | CI6: KESESUAIAN MARPOL (3) | CJ6: OPERASIONAL EFISIEN PERMESINAN LAUT (4) | CK6: SISTEM MANUVER ME (5) | CL6: PELATIHAN KESELAMATAN RATING (6) | CM6: LATIHAN HIDROLIK (7) | CN6: PRAKTEK KELISTRIKAN (8) | CO6: MANAJEMEN SUMBER DAYA BRIDGE (9) | CP6: ANALISIS MENDASAR (10) | CQ6: PERWIRA KESELAMATAN KAPAL (11) | CR6: OTOMATISASI DAN KONTROL (12) | CS6: TEORI PRAKTEK PENANGANAN KAPAL (13) | CT6: COMMAND ORIENTATION COURSE (14) | CU6: MEMASUKI RUANG TERTUTUP (15) | CV6: Tingkah laku & Sikap | DB6: PENILAIN & P UMUM | DE6: Kepemimpinan | DI6: 1 | DJ6: 2 | DK6: 3 | DL6: 4 | DM6: 5 | DN6: 6 | DP6: PRAKTEK KELISTRIKAN (1) | DQ6: ANALISIS PENYEBAB MASALAH (2) | DR6: PERWIWA KESELAMATAN KAPAL (3) | DS6: INSPEKSI PORT STATE CONTROL (4) | DT6: TEORI & PRAKTEK SHIP HANDLING (5) | DU6: MEMASUKI RUANG TERTUTUP (6) | DV6: KURSUS COMMAND ORIENTED (7) | DW6: PELATIHAN KESELAMATAN TERPADU U/ RATINGS (8) | DX6: PELAJARAN PUMP MAN (9) | DY6: BASIC TANKER OPERATION (10) | DZ6: SMK (11) | EA6: MARPOL COMPLIANCE (12) | EB6: EFFICIENT OPERATION OF MARINE MACHINERY (13) | EC6: SISTIM MANUVERING ME (14) | ED6: AUTOMATION & CONTROL (15) | EE6: BRIDGE RESOURCE MANAGEMENT (16) | EF6: Senior Officer | EG6: Junior Officer | EH6: Rating
M7: TL | N7: SS | O7: I | P7: LOY | Q7: ANT | R7: KS | S7: PKR | T7: IN INT | U7: OUT INT | V7: MM | W7: MT | X7: MAK | Y7: HK | BD7: TNG | BE7: KW | BF7: ATS | BG7: HAD | BH7: PRO | BI7: MD | BJ7: LOY | BK7: KMI | BL7: KMM | BM7: INS | BN7: PK | BO7: MMB | BP7: KKK | BQ7: HDB | BR7: MW | CV7: TNG | CW7: SRG | CX7: I | CY7: ATS | CZ7: LOY | DA7: KOP | DB7: LOG | DC7: IN INS | DD7: OUT INT | DE7: MMK | DF7: KMT | DG7: KMC | DH7: KKK
B8: KM. AKASHIA | H8: 20130270 | I8: HADI SUCIPTO | J8: MUALIM I | L8: 0 tahun 0 bulan 17 hari | AN8: =AVERAGE(M8:AM8) -> #DIV/0! | CF8: =AVERAGE(BE8:CE8) -> #DIV/0! | DO8: =AVERAGE(CN8:DN8) -> #DIV/0! | EF8: =IF(AN8<=2,"VERY POOR",IF(AN8<=6.5,"POOR",IF(AN8<=8,"NEED TO DEVELOP",IF(AN8<=8.9,"GOOD","VERY GOOD")))) -> #DIV/0! | EG8: =IF(CF8<=2,"VERY POOR",IF(CF8<=6.5,"POOR",IF(CF8<=8,"NEED TO DEVELOP",IF(CF8<=8.9,"GOOD","VERY GOOD")))) -> #DIV/0! | EH8: =IF(DO8<=2,"VERY POOR",IF(DO8<=6.5,"POOR",IF(DO8<=8,"NEED TO DEVELOP",IF(DO8<=8.9,"GOOD","VERY GOOD")))) -> #DIV/0!
B9: KM. AKASHIA | H9: 20150439 | I9: KUSWARI | J9: MUALIM II | L9: 0 tahun 1 bulan 12 hari | AN9: =AVERAGE(M9:AM9) -> #DIV/0! | CF9: =AVERAGE(BE9:CE9) -> #DIV/0! | DO9: =AVERAGE(CN9:DN9) -> #DIV/0! | EF9: =IF(AN9<=2,"VERY POOR",IF(AN9<=6.5,"POOR",IF(AN9<=8,"NEED TO DEVELOP",IF(AN9<=8.9,"GOOD","VERY GOOD")))) -> #DIV/0! | EG9: =IF(CF9<=2,"VERY POOR",IF(CF9<=6.5,"POOR",IF(CF9<=8,"NEED TO DEVELOP",IF(CF9<=8.9,"GOOD","VERY GOOD")))) -> #DIV/0! | EH9: =IF(DO9<=2,"VERY POOR",IF(DO9<=6.5,"POOR",IF(DO9<=8,"NEED TO DEVELOP",IF(DO9<=8.9,"GOOD","VERY GOOD")))) -> #DIV/0!
B10: KM. AKASHIA | H10: 20210262 | I10: ANGGORO BAYU AJI | J10: MUALIM III | L10: 0 tahun 4 bulan 1 hari | AN10: =AVERAGE(M10:AM10) -> #DIV/0! | BD10: 8 | BE10: 8 | BF10: 8 | BG10: 8 | BH10: 8 | BI10: 8 | BJ10: 8 | BK10: 8 | BL10: 8 | BM10: 8 | BN10: 7 | BO10: 8 | BP10: 8 | BQ10: 8 | BR10: 7 | BS10: 8 | BT10: 8 | BU10: 8 | BV10: 8 | BW10: 8 | BX10: 8 | BY10: 8 | BZ10: 8 | CA10: 8 | CB10: 7 | CC10: 7 | CD10: 8 | CE10: 8 | CF10: =AVERAGE(BE10:CE10) -> 7.8518519 | DO10: =AVERAGE(CN10:DN10) -> #DIV/0! | EF10: =IF(AN10<=2,"VERY POOR",IF(AN10<=6.5,"POOR",IF(AN10<=8,"NEED TO DEVELOP",IF(AN10<=8.9,"GOOD","VERY GOOD")))) -> #DIV/0! | EG10: =IF(CF10<=2,"VERY POOR",IF(CF10<=6.5,"POOR",IF(CF10<=8,"NEED TO DEVELOP",IF(CF10<=8.9,"GOOD","VERY GOOD")))) -> NEED TO DEVELOP | EH10: =IF(DO10<=2,"VERY POOR",IF(DO10<=6.5,"POOR",IF(DO10<=8,"NEED TO DEVELOP",IF(DO10<=8.9,"GOOD","VERY GOOD")))) -> #DIV/0!
B11: KM. AKASHIA | H11: 20180182 | I11: MU'ARIEFFATCHURROHMAN AR. R | J11: MASINIS II | L11: 0 tahun 2 bulan 16 hari | AN11: =AVERAGE(M11:AM11) -> #DIV/0! | BD11: 8 | BE11: 8 | BF11: 8 | BG11: 8 | BH11: 8 | BI11: 8 | BJ11: 8 | BK11: 8 | BL11: 8 | BM11: 8 | BN11: 8 | BO11: 8 | BP11: 8 | BQ11: 8 | BR11: 8 | BS11: 8 | BT11: 8 | BU11: 8 | BV11: 8 | BW11: 8 | BX11: 8 | BY11: 8 | BZ11: 8 | CA11: 8 | CB11: 8 | CC11: 8 | CD11: 8 | CE11: 8 | CF11: =AVERAGE(BE11:CE11) -> 8 | DO11: =AVERAGE(CN11:DN11) -> #DIV/0! | EF11: =IF(AN11<=2,"VERY POOR",IF(AN11<=6.5,"POOR",IF(AN11<=8,"NEED TO DEVELOP",IF(AN11<=8.9,"GOOD","VERY GOOD")))) -> #DIV/0! | EG11: =IF(CF11<=2,"VERY POOR",IF(CF11<=6.5,"POOR",IF(CF11<=8,"NEED TO DEVELOP",IF(CF11<=8.9,"GOOD","VERY GOOD")))) -> NEED TO DEVELOP | EH11: =IF(DO11<=2,"VERY POOR",IF(DO11<=6.5,"POOR",IF(DO11<=8,"NEED TO DEVELOP",IF(DO11<=8.9,"GOOD","VERY GOOD")))) -> #DIV/0!
B12: KM. AKASHIA | H12: 20170334 | I12: KHAIRUR ROZIKIN | J12: MASINIS III | L12: 0 tahun 6 bulan 18 hari | AN12: =AVERAGE(M12:AM12) -> #DIV/0! | BD12: 8 | BE12: 8 | BF12: 8 | BG12: 8 | BH12: 8 | BI12: 8 | BJ12: 8 | BK12: 8 | BL12: 8 | BM12: 8 | BN12: 8 | BO12: 8 | BP12: 8 | BQ12: 8 | BR12: 8 | BS12: 8 | BT12: 8 | BU12: 8 | BV12: 8 | BW12: 8 | BX12: 8 | BY12: 8 | BZ12: 8 | CA12: 8 | CB12: 8 | CC12: 8 | CD12: 8 | CE12: 8 | CF12: =AVERAGE(BE12:CE12) -> 8 | DO12: =AVERAGE(CN12:DN12) -> #DIV/0! | EF12: =IF(AN12<=2,"VERY POOR",IF(AN12<=6.5,"POOR",IF(AN12<=8,"NEED TO DEVELOP",IF(AN12<=8.9,"GOOD","VERY GOOD")))) -> #DIV/0! | EG12: =IF(CF12<=2,"VERY POOR",IF(CF12<=6.5,"POOR",IF(CF12<=8,"NEED TO DEVELOP",IF(CF12<=8.9,"GOOD","VERY GOOD")))) -> NEED TO DEVELOP | EH12: =IF(DO12<=2,"VERY POOR",IF(DO12<=6.5,"POOR",IF(DO12<=8,"NEED TO DEVELOP",IF(DO12<=8.9,"GOOD","VERY GOOD")))) -> #DIV/0!
B13: KM. AKASHIA | H13: 20200138 | I13: MUHAMMAD THOYIB ABDULLAH | J13: SERANG | L13: 0 tahun 5 bulan 19 hari | AN13: =AVERAGE(M13:AM13) -> #DIV/0! | CF13: =AVERAGE(BE13:CE13) -> #DIV/0! | CV13: 8 | CW13: 8 | CX13: 7 | CY13: 8 | CZ13: 8 | DA13: 8 | DB13: 8 | DC13: 8 | DD13: 8 | DI13: 8 | DJ13: 7 | DK13: 8 | DL13: 8 | DM13: 7 | DN13: 8 | DO13: =AVERAGE(CN13:DN13) -> 7.8 | EF13: =IF(AN13<=2,"VERY POOR",IF(AN13<=6.5,"POOR",IF(AN13<=8,"NEED TO DEVELOP",IF(AN13<=8.9,"GOOD","VERY GOOD")))) -> #DIV/0! | EG13: =IF(CF13<=2,"VERY POOR",IF(CF13<=6.5,"POOR",IF(CF13<=8,"NEED TO DEVELOP",IF(CF13<=8.9,"GOOD","VERY GOOD")))) -> #DIV/0! | EH13: =IF(DO13<=2,"VERY POOR",IF(DO13<=6.5,"POOR",IF(DO13<=8,"NEED TO DEVELOP",IF(DO13<=8.9,"GOOD","VERY GOOD")))) -> NEED TO DEVELOP
B14: KM. AKASHIA | H14: 20240205 | I14: ABDULLAH | J14: JURU MUDI | L14: 0 tahun 11 bulan 6 hari | AN14: =AVERAGE(M14:AM14) -> #DIV/0! | CF14: =AVERAGE(BE14:CE14) -> #DIV/0! | CV14: 8 | CW14: 8 | CX14: 7 | CY14: 8 | CZ14: 7 | DA14: 7 | DB14: 7 | DC14: 8 | DD14: 8 | DI14: 8 | DJ14: 8 | DK14: 8 | DL14: 7 | DM14: 7 | DN14: 7 | DO14: =AVERAGE(CN14:DN14) -> 7.5333333 | EF14: =IF(AN14<=2,"VERY POOR",IF(AN14<=6.5,"POOR",IF(AN14<=8,"NEED TO DEVELOP",IF(AN14<=8.9,"GOOD","VERY GOOD")))) -> #DIV/0! | EG14: =IF(CF14<=2,"VERY POOR",IF(CF14<=6.5,"POOR",IF(CF14<=8,"NEED TO DEVELOP",IF(CF14<=8.9,"GOOD","VERY GOOD")))) -> #DIV/0! | EH14: =IF(DO14<=2,"VERY POOR",IF(DO14<=6.5,"POOR",IF(DO14<=8,"NEED TO DEVELOP",IF(DO14<=8.9,"GOOD","VERY GOOD")))) -> NEED TO DEVELOP
B15: KM. AKASHIA | H15: 20240286 | I15: ADITYA WARMAN | J15: JURU MUDI | L15: 0 tahun 9 bulan 16 hari | AN15: =AVERAGE(M15:AM15) -> #DIV/0! | CF15: =AVERAGE(BE15:CE15) -> #DIV/0! | CV15: 8 | CW15: 8 | CX15: 7 | CY15: 7 | CZ15: 7 | DA15: 7 | DB15: 8 | DC15: 8 | DD15: 8 | DI15: 8 | DJ15: 8 | DK15: 7 | DL15: 7 | DM15: 7 | DN15: 8 | DO15: =AVERAGE(CN15:DN15) -> 7.5333333 | EF15: =IF(AN15<=2,"VERY POOR",IF(AN15<=6.5,"POOR",IF(AN15<=8,"NEED TO DEVELOP",IF(AN15<=8.9,"GOOD","VERY GOOD")))) -> #DIV/0! | EG15: =IF(CF15<=2,"VERY POOR",IF(CF15<=6.5,"POOR",IF(CF15<=8,"NEED TO DEVELOP",IF(CF15<=8.9,"GOOD","VERY GOOD")))) -> #DIV/0! | EH15: =IF(DO15<=2,"VERY POOR",IF(DO15<=6.5,"POOR",IF(DO15<=8,"NEED TO DEVELOP",IF(DO15<=8.9,"GOOD","VERY GOOD")))) -> NEED TO DEVELOP
B16: KM. AKASHIA | H16: 20130067 | I16: GURUH CHRISTIANTOKO | J16: JURU MUDI | L16: 0 tahun 4 bulan 1 hari | AN16: =AVERAGE(M16:AM16) -> #DIV/0! | CF16: =AVERAGE(BE16:CE16) -> #DIV/0! | CV16: 8 | CW16: 8 | CX16: 7 | CY16: 7 | CZ16: 7 | DA16: 8 | DB16: 8 | DC16: 8 | DD16: 8 | DI16: 7 | DJ16: 8 | DK16: 7 | DL16: 7 | DM16: 7 | DN16: 7 | DO16: =AVERAGE(CN16:DN16) -> 7.4666667 | EF16: =IF(AN16<=2,"VERY POOR",IF(AN16<=6.5,"POOR",IF(AN16<=8,"NEED TO DEVELOP",IF(AN16<=8.9,"GOOD","VERY GOOD")))) -> #DIV/0! | EG16: =IF(CF16<=2,"VERY POOR",IF(CF16<=6.5,"POOR",IF(CF16<=8,"NEED TO DEVELOP",IF(CF16<=8.9,"GOOD","VERY GOOD")))) -> #DIV/0! | EH16: =IF(DO16<=2,"VERY POOR",IF(DO16<=6.5,"POOR",IF(DO16<=8,"NEED TO DEVELOP",IF(DO16<=8.9,"GOOD","VERY GOOD")))) -> NEED TO DEVELOP
B17: KM. AKASHIA | H17: 20240380 | I17: AJI PUTRO PRAYOGO | J17: JURU MINYAK | L17: 0 tahun 6 bulan 22 hari | AN17: =AVERAGE(M17:AM17) -> #DIV/0! | CF17: =AVERAGE(BE17:CE17) -> #DIV/0! | CV17: 8 | CW17: 8 | CX17: 8 | CY17: 8 | CZ17: 8 | DA17: 8 | DB17: 8 | DC17: 8 | DD17: 8 | DI17: 8 | DJ17: 8 | DK17: 8 | DL17: 8 | DM17: 8 | DN17: 8 | DO17: =AVERAGE(CN17:DN17) -> 8 | EF17: =IF(AN17<=2,"VERY POOR",IF(AN17<=6.5,"POOR",IF(AN17<=8,"NEED TO DEVELOP",IF(AN17<=8.9,"GOOD","VERY GOOD")))) -> #DIV/0! | EG17: =IF(CF17<=2,"VERY POOR",IF(CF17<=6.5,"POOR",IF(CF17<=8,"NEED TO DEVELOP",IF(CF17<=8.9,"GOOD","VERY GOOD")))) -> #DIV/0! | EH17: =IF(DO17<=2,"VERY POOR",IF(DO17<=6.5,"POOR",IF(DO17<=8,"NEED TO DEVELOP",IF(DO17<=8.9,"GOOD","VERY GOOD")))) -> NEED TO DEVELOP
B18: KM. AKASHIA | H18: 20230421 | I18: ANGGA YUDA KURNIAWAN | J18: JURU MINYAK | L18: 0 tahun 1 bulan 4 hari | AN18: =AVERAGE(M18:AM18) -> #DIV/0! | CF18: =AVERAGE(BE18:CE18) -> #DIV/0! | DO18: =AVERAGE(CN18:DN18) -> #DIV/0! | EF18: =IF(AN18<=2,"VERY POOR",IF(AN18<=6.5,"POOR",IF(AN18<=8,"NEED TO DEVELOP",IF(AN18<=8.9,"GOOD","VERY GOOD")))) -> #DIV/0! | EG18: =IF(CF18<=2,"VERY POOR",IF(CF18<=6.5,"POOR",IF(CF18<=8,"NEED TO DEVELOP",IF(CF18<=8.9,"GOOD","VERY GOOD")))) -> #DIV/0! | EH18: =IF(DO18<=2,"VERY POOR",IF(DO18<=6.5,"POOR",IF(DO18<=8,"NEED TO DEVELOP",IF(DO18<=8.9,"GOOD","VERY GOOD")))) -> #DIV/0!
B19: KM. AKASHIA | H19: 20250042 | I19: DIO RAMADHANI PUTRA ARYADEWA | J19: JURU MINYAK | L19: 0 tahun 4 bulan 1 hari | AN19: =AVERAGE(M19:AM19) -> #DIV/0! | CF19: =AVERAGE(BE19:CE19) -> #DIV/0! | CV19: 8 | CW19: 8 | CX19: 8 | CY19: 8 | CZ19: 8 | DA19: 8 | DB19: 8 | DC19: 8 | DD19: 8 | DI19: 8 | DJ19: 8 | DK19: 8 | DL19: 8 | DM19: 8 | DN19: 8 | DO19: =AVERAGE(CN19:DN19) -> 8 | EF19: =IF(AN19<=2,"VERY POOR",IF(AN19<=6.5,"POOR",IF(AN19<=8,"NEED TO DEVELOP",IF(AN19<=8.9,"GOOD","VERY GOOD")))) -> #DIV/0! | EG19: =IF(CF19<=2,"VERY POOR",IF(CF19<=6.5,"POOR",IF(CF19<=8,"NEED TO DEVELOP",IF(CF19<=8.9,"GOOD","VERY GOOD")))) -> #DIV/0! | EH19: =IF(DO19<=2,"VERY POOR",IF(DO19<=6.5,"POOR",IF(DO19<=8,"NEED TO DEVELOP",IF(DO19<=8.9,"GOOD","VERY GOOD")))) -> NEED TO DEVELOP
B20: KM. AKASHIA | H20: 20240060 | I20: ERIEK NOVERIANTO | J20: JURU MASAK I | L20: 0 tahun 2 bulan 22 hari | AN20: =AVERAGE(M20:AM20) -> #DIV/0! | CF20: =AVERAGE(BE20:CE20) -> #DIV/0! | CV20: 8 | CW20: 7 | CX20: 8 | CY20: 8 | CZ20: 7 | DA20: 7 | DB20: 7 | DC20: 7 | DD20: 7 | DI20: 7 | DJ20: 7 | DK20: 8 | DL20: 8 | DM20: 7 | DN20: 7 | DO20: =AVERAGE(CN20:DN20) -> 7.3333333 | EF20: =IF(AN20<=2,"VERY POOR",IF(AN20<=6.5,"POOR",IF(AN20<=8,"NEED TO DEVELOP",IF(AN20<=8.9,"GOOD","VERY GOOD")))) -> #DIV/0! | EG20: =IF(CF20<=2,"VERY POOR",IF(CF20<=6.5,"POOR",IF(CF20<=8,"NEED TO DEVELOP",IF(CF20<=8.9,"GOOD","VERY GOOD")))) -> #DIV/0! | EH20: =IF(DO20<=2,"VERY POOR",IF(DO20<=6.5,"POOR",IF(DO20<=8,"NEED TO DEVELOP",IF(DO20<=8.9,"GOOD","VERY GOOD")))) -> NEED TO DEVELOP
B21: KM. ARMADA PERMATA | H21: 20170250 | I21: LUIS DIYANTO RENOL HIDAYAT | J21: MUALIM I | L21: 0 tahun 5 bulan 12 hari | M21: 8 | N21: 7 | O21: 8 | P21: 8 | Q21: 8 | R21: 7 | S21: 8 | T21: 8 | U21: 8 | V21: 7 | W21: 8 | X21: 8 | Y21: 7 | Z21: 8 | AA21: 8 | AB21: 8 | AC21: 8 | AD21: 8 | AE21: 8 | AF21: 7 | AG21: 8 | AH21: 8 | AI21: 7 | AJ21: 8 | AK21: 8 | AL21: 7 | AM21: 7 | AN21: =AVERAGE(M21:AM21) -> 7.7037037 | CF21: =AVERAGE(BE21:CE21) -> #DIV/0! | DO21: =AVERAGE(CN21:DN21) -> #DIV/0! | EF21: =IF(AN21<=2,"VERY POOR",IF(AN21<=6.5,"POOR",IF(AN21<=8,"NEED TO DEVELOP",IF(AN21<=8.9,"GOOD","VERY GOOD")))) -> NEED TO DEVELOP | EG21: =IF(CF21<=2,"VERY POOR",IF(CF21<=6.5,"POOR",IF(CF21<=8,"NEED TO DEVELOP",IF(CF21<=8.9,"GOOD","VERY GOOD")))) -> #DIV/0! | EH21: =IF(DO21<=2,"VERY POOR",IF(DO21<=6.5,"POOR",IF(DO21<=8,"NEED TO DEVELOP",IF(DO21<=8.9,"GOOD","VERY GOOD")))) -> #DIV/0!
B22: KM. ARMADA PERMATA | H22: 20160124 | I22: ANDRI RUSADI | J22: MUALIM II | L22: 0 tahun 5 bulan 21 hari | AN22: =AVERAGE(M22:AM22) -> #DIV/0! | BD22: 7 | BE22: 8 | BF22: 7 | BG22: 8 | BH22: 8 | BI22: 7 | BJ22: 8 | BK22: 8 | BL22: 8 | BM22: 8 | BN22: 8 | BO22: 7 | BP22: 8 | BQ22: 8 | BR22: 8 | BS22: 8 | BT22: 8 | BU22: 8 | BV22: 8 | BW22: 8 | BX22: 8 | BY22: 7 | BZ22: 8 | CA22: 8 | CB22: 7 | CC22: 8 | CD22: 8 | CE22: 8 | CF22: =AVERAGE(BE22:CE22) -> 7.8148148 | CS22: 1 | DO22: =AVERAGE(CN22:DN22) -> 1 | EF22: =IF(AN22<=2,"VERY POOR",IF(AN22<=6.5,"POOR",IF(AN22<=8,"NEED TO DEVELOP",IF(AN22<=8.9,"GOOD","VERY GOOD")))) -> #DIV/0! | EG22: =IF(CF22<=2,"VERY POOR",IF(CF22<=6.5,"POOR",IF(CF22<=8,"NEED TO DEVELOP",IF(CF22<=8.9,"GOOD","VERY GOOD")))) -> NEED TO DEVELOP | EH22: =IF(DO22<=2,"VERY POOR",IF(DO22<=6.5,"POOR",IF(DO22<=8,"NEED TO DEVELOP",IF(DO22<=8.9,"GOOD","VERY GOOD")))) -> VERY POOR
B23: KM. ARMADA PERMATA | H23: 20200298 | I23: FAHMI AMINUDDIN | J23: MUALIM III | L23: 0 tahun 0 bulan 14 hari | AN23: =AVERAGE(M23:AM23) -> #DIV/0! | CF23: =AVERAGE(BE23:CE23) -> #DIV/0! | DO23: =AVERAGE(CN23:DN23) -> #DIV/0! | EF23: =IF(AN23<=2,"VERY POOR",IF(AN23<=6.5,"POOR",IF(AN23<=8,"NEED TO DEVELOP",IF(AN23<=8.9,"GOOD","VERY GOOD")))) -> #DIV/0! | EG23: =IF(CF23<=2,"VERY POOR",IF(CF23<=6.5,"POOR",IF(CF23<=8,"NEED TO DEVELOP",IF(CF23<=8.9,"GOOD","VERY GOOD")))) -> #DIV/0! | EH23: =IF(DO23<=2,"VERY POOR",IF(DO23<=6.5,"POOR",IF(DO23<=8,"NEED TO DEVELOP",IF(DO23<=8.9,"GOOD","VERY GOOD")))) -> #DIV/0!
B24: KM. ARMADA PERMATA | H24: 20060306 | I24: DIAN RIANTO | J24: MASINIS I | L24: 0 tahun 2 bulan 29 hari | M24: 8 | N24: 8 | O24: 8 | P24: 8 | Q24: 8 | R24: 8 | S24: 8 | T24: 8 | U24: 8 | V24: 8 | W24: 8 | X24: 8 | Y24: 8 | Z24: 8 | AA24: 8 | AB24: 8 | AC24: 8 | AD24: 8 | AE24: 8 | AF24: 8 | AG24: 8 | AH24: 8 | AI24: 8 | AJ24: 8 | AK24: 8 | AL24: 8 | AM24: 8 | AN24: =AVERAGE(M24:AM24) -> 8 | AO24: 1 | AQ24: 1 | AR24: 1 | AS24: 1 | AU24: 1 | AX24: 1 | AY24: 1 | BA24: 1 | BB24: 1 | CF24: =AVERAGE(BE24:CE24) -> #DIV/0! | DO24: =AVERAGE(CN24:DN24) -> #DIV/0! | EF24: =IF(AN24<=2,"VERY POOR",IF(AN24<=6.5,"POOR",IF(AN24<=8,"NEED TO DEVELOP",IF(AN24<=8.9,"GOOD","VERY GOOD")))) -> NEED TO DEVELOP | EG24: =IF(CF24<=2,"VERY POOR",IF(CF24<=6.5,"POOR",IF(CF24<=8,"NEED TO DEVELOP",IF(CF24<=8.9,"GOOD","VERY GOOD")))) -> #DIV/0! | EH24: =IF(DO24<=2,"VERY POOR",IF(DO24<=6.5,"POOR",IF(DO24<=8,"NEED TO DEVELOP",IF(DO24<=8.9,"GOOD","VERY GOOD")))) -> #DIV/0!
B25: KM. ARMADA PERMATA | H25: 20140500 | I25: DEDE RUKMANA | J25: MASINIS II | L25: 0 tahun 8 bulan 3 hari | AN25: =AVERAGE(M25:AM25) -> #DIV/0! | BD25: 8 | BE25: 8 | BF25: 8 | BG25: 8 | BH25: 8 | BI25: 8 | BJ25: 8 | BK25: 8 | BL25: 8 | BM25: 7.6 | BN25: 7.7 | BO25: 8 | BP25: 8 | BQ25: 8 | BR25: 8 | BS25: 8 | BT25: 8 | BU25: 8 | BV25: 8 | BW25: 8 | BX25: 8 | BY25: 8 | BZ25: 8 | CA25: 8 | CB25: 8 | CC25: 8 | CD25: 8 | CE25: 8 | CF25: =AVERAGE(BE25:CE25) -> 7.9740741 | CG25: 1 | CI25: 1 | CJ25: 1 | CK25: 1 | CM25: 1 | CQ25: 1 | CR25: 1 | CS25: 1 | DO25: =AVERAGE(CN25:DN25) -> 1 | EF25: =IF(AN25<=2,"VERY POOR",IF(AN25<=6.5,"POOR",IF(AN25<=8,"NEED TO DEVELOP",IF(AN25<=8.9,"GOOD","VERY GOOD")))) -> #DIV/0! | EG25: =IF(CF25<=2,"VERY POOR",IF(CF25<=6.5,"POOR",IF(CF25<=8,"NEED TO DEVELOP",IF(CF25<=8.9,"GOOD","VERY GOOD")))) -> NEED TO DEVELOP | EH25: =IF(DO25<=2,"VERY POOR",IF(DO25<=6.5,"POOR",IF(DO25<=8,"NEED TO DEVELOP",IF(DO25<=8.9,"GOOD","VERY GOOD")))) -> VERY POOR
B26: KM. ARMADA PERMATA | H26: 20150140 | I26: RIVAY LAHU | J26: MASINIS III | L26: 0 tahun 5 bulan 21 hari | AN26: =AVERAGE(M26:AM26) -> #DIV/0! | BD26: 7.8 | BE26: 7.8 | BF26: 7.8 | BG26: 7.8 | BH26: 7.8 | BI26: 7.8 | BJ26: 7.8 | BK26: 7.9 | BL26: 7.8 | BM26: 7.9 | BN26: 7.8 | BO26: 7.9 | BP26: 7.9 | BQ26: 7.9 | BR26: 7.9 | BS26: 7.9 | BT26: 7.9 | BU26: 7.9 | BV26: 7.9 | BW26: 7.9 | BX26: 7.9 | BY26: 7.9 | BZ26: 8 | CA26: 7.9 | CB26: 7.8 | CC26: 7.8 | CD26: 7.8 | CE26: 7.5 | CF26: =AVERAGE(BE26:CE26) -> 7.8481481 | CG26: 1 | CI26: 1 | CJ26: 1 | CK26: 1 | CL26: 1 | CM26: 1 | CN26: 1 | CP26: 1 | CQ26: 1 | CR26: 1 | CS26: 1 | CU26: 1 | DO26: =AVERAGE(CN26:DN26) -> 1 | EF26: =IF(AN26<=2,"VERY POOR",IF(AN26<=6.5,"POOR",IF(AN26<=8,"NEED TO DEVELOP",IF(AN26<=8.9,"GOOD","VERY GOOD")))) -> #DIV/0! | EG26: =IF(CF26<=2,"VERY POOR",IF(CF26<=6.5,"POOR",IF(CF26<=8,"NEED TO DEVELOP",IF(CF26<=8.9,"GOOD","VERY GOOD")))) -> NEED TO DEVELOP | EH26: =IF(DO26<=2,"VERY POOR",IF(DO26<=6.5,"POOR",IF(DO26<=8,"NEED TO DEVELOP",IF(DO26<=8.9,"GOOD","VERY GOOD")))) -> VERY POOR
B27: KM. ARMADA PERMATA | H27: 20160471 | I27: MOCH IRVAN | J27: SERANG | L27: 0 tahun 11 bulan 1 hari | AN27: =AVERAGE(M27:AM27) -> #DIV/0! | CF27: =AVERAGE(BE27:CE27) -> #DIV/0! | CV27: 8 | CW27: 8 | CX27: 8 | CY27: 7 | CZ27: 8 | DA27: 8 | DB27: 8 | DC27: 8 | DD27: 7 | DE27: 8 | DF27: 8 | DG27: 8 | DH27: 8 | DI27: 8 | DJ27: 7 | DK27: 8 | DL27: 8 | DM27: 7 | DN27: 7 | DO27: =AVERAGE(CN27:DN27) -> 7.7368421 | EF27: =IF(AN27<=2,"VERY POOR",IF(AN27<=6.5,"POOR",IF(AN27<=8,"NEED TO DEVELOP",IF(AN27<=8.9,"GOOD","VERY GOOD")))) -> #DIV/0! | EG27: =IF(CF27<=2,"VERY POOR",IF(CF27<=6.5,"POOR",IF(CF27<=8,"NEED TO DEVELOP",IF(CF27<=8.9,"GOOD","VERY GOOD")))) -> #DIV/0! | EH27: =IF(DO27<=2,"VERY POOR",IF(DO27<=6.5,"POOR",IF(DO27<=8,"NEED TO DEVELOP",IF(DO27<=8.9,"GOOD","VERY GOOD")))) -> NEED TO DEVELOP
B28: KM. ARMADA PERMATA | H28: 20240098 | I28: FEBRI DARMA JANRI BUTAR-BUTAR | J28: JURU MUDI | L28: 0 tahun 0 bulan 24 hari | AN28: =AVERAGE(M28:AM28) -> #DIV/0! | CF28: =AVERAGE(BE28:CE28) -> #DIV/0! | DO28: =AVERAGE(CN28:DN28) -> #DIV/0! | EF28: =IF(AN28<=2,"VERY POOR",IF(AN28<=6.5,"POOR",IF(AN28<=8,"NEED TO DEVELOP",IF(AN28<=8.9,"GOOD","VERY GOOD")))) -> #DIV/0! | EG28: =IF(CF28<=2,"VERY POOR",IF(CF28<=6.5,"POOR",IF(CF28<=8,"NEED TO DEVELOP",IF(CF28<=8.9,"GOOD","VERY GOOD")))) -> #DIV/0! | EH28: =IF(DO28<=2,"VERY POOR",IF(DO28<=6.5,"POOR",IF(DO28<=8,"NEED TO DEVELOP",IF(DO28<=8.9,"GOOD","VERY GOOD")))) -> #DIV/0!
B29: KM. ARMADA PERMATA | H29: 20240014 | I29: MAULANA | J29: JURU MUDI | L29: 0 tahun 2 bulan 18 hari | AN29: =AVERAGE(M29:AM29) -> #DIV/0! | CF29: =AVERAGE(BE29:CE29) -> #DIV/0! | CV29: 8 | CW29: 7 | CX29: 8 | CY29: 8 | CZ29: 8 | DA29: 7 | DB29: 8 | DC29: 8 | DD29: 8 | DI29: 8 | DJ29: 8 | DK29: 8 | DL29: 7 | DM29: 7 | DN29: 8 | DO29: =AVERAGE(CN29:DN29) -> 7.7333333 | EF29: =IF(AN29<=2,"VERY POOR",IF(AN29<=6.5,"POOR",IF(AN29<=8,"NEED TO DEVELOP",IF(AN29<=8.9,"GOOD","VERY GOOD")))) -> #DIV/0! | EG29: =IF(CF29<=2,"VERY POOR",IF(CF29<=6.5,"POOR",IF(CF29<=8,"NEED TO DEVELOP",IF(CF29<=8.9,"GOOD","VERY GOOD")))) -> #DIV/0! | EH29: =IF(DO29<=2,"VERY POOR",IF(DO29<=6.5,"POOR",IF(DO29<=8,"NEED TO DEVELOP",IF(DO29<=8.9,"GOOD","VERY GOOD")))) -> NEED TO DEVELOP
B30: KM. ARMADA PERMATA | H30: 20240309 | I30: SYAHRIL HADRAWI | J30: JURU MUDI | L30: 0 tahun 8 bulan 22 hari | AN30: =AVERAGE(M30:AM30) -> #DIV/0! | CF30: =AVERAGE(BE30:CE30) -> #DIV/0! | CV30: 8 | CW30: 8 | CX30: 8 | CY30: 8 | CZ30: 8 | DA30: 7 | DB30: 8 | DC30: 8 | DD30: 8 | DI30: 8 | DJ30: 8 | DK30: 8 | DL30: 7 | DM30: 7 | DN30: 8 | DO30: =AVERAGE(CN30:DN30) -> 7.8 | EF30: =IF(AN30<=2,"VERY POOR",IF(AN30<=6.5,"POOR",IF(AN30<=8,"NEED TO DEVELOP",IF(AN30<=8.9,"GOOD","VERY GOOD")))) -> #DIV/0! | EG30: =IF(CF30<=2,"VERY POOR",IF(CF30<=6.5,"POOR",IF(CF30<=8,"NEED TO DEVELOP",IF(CF30<=8.9,"GOOD","VERY GOOD")))) -> #DIV/0! | EH30: =IF(DO30<=2,"VERY POOR",IF(DO30<=6.5,"POOR",IF(DO30<=8,"NEED TO DEVELOP",IF(DO30<=8.9,"GOOD","VERY GOOD")))) -> NEED TO DEVELOP
B31: KM. ARMADA PERMATA | H31: 20220121 | I31: SAS TRIYONO | J31: ELECTRICIAN | L31: 0 tahun 9 bulan 2 hari | AN31: =AVERAGE(M31:AM31) -> #DIV/0! | CF31: =AVERAGE(BE31:CE31) -> #DIV/0! | CV31: 8 | CW31: 8 | CX31: 8 | CY31: 8 | CZ31: 8 | DA31: 8 | DB31: 8 | DC31: 8 | DD31: 8 | DI31: 8 | DJ31: 8 | DK31: 8 | DL31: 8 | DM31: 8 | DN31: 8 | DO31: =AVERAGE(CN31:DN31) -> 8 | DP31: 1 | DQ31: 1 | DR31: 1 | DT31: 1 | DW31: 1 | EA31: 1 | ED31: 1 | EF31: =IF(AN31<=2,"VERY POOR",IF(AN31<=6.5,"POOR",IF(AN31<=8,"NEED TO DEVELOP",IF(AN31<=8.9,"GOOD","VERY GOOD")))) -> #DIV/0! | EG31: =IF(CF31<=2,"VERY POOR",IF(CF31<=6.5,"POOR",IF(CF31<=8,"NEED TO DEVELOP",IF(CF31<=8.9,"GOOD","VERY GOOD")))) -> #DIV/0! | EH31: =IF(DO31<=2,"VERY POOR",IF(DO31<=6.5,"POOR",IF(DO31<=8,"NEED TO DEVELOP",IF(DO31<=8.9,"GOOD","VERY GOOD")))) -> NEED TO DEVELOP
B32: KM. ARMADA PERMATA | H32: 20180299 | I32: SIGIT KAMSENO | J32: MANDOR MESIN | L32: 0 tahun 3 bulan 19 hari | AN32: =AVERAGE(M32:AM32) -> #DIV/0! | CF32: =AVERAGE(BE32:CE32) -> #DIV/0! | CV32: 7.5 | CW32: 7.5 | CX32: 7.5 | CY32: 7.5 | CZ32: 7.5 | DA32: 7.4 | DB32: 7.4 | DC32: 7.3 | DD32: 7.3 | DI32: 7.4 | DJ32: 7.4 | DK32: 7.6 | DL32: 7.5 | DM32: 7.3 | DN32: 7.5 | DO32: =AVERAGE(CN32:DN32) -> 7.44 | DQ32: 1 | DT32: 1 | DW32: 1 | DZ32: 1 | EB32: 1 | EF32: =IF(AN32<=2,"VERY POOR",IF(AN32<=6.5,"POOR",IF(AN32<=8,"NEED TO DEVELOP",IF(AN32<=8.9,"GOOD","VERY GOOD")))) -> #DIV/0! | EG32: =IF(CF32<=2,"VERY POOR",IF(CF32<=6.5,"POOR",IF(CF32<=8,"NEED TO DEVELOP",IF(CF32<=8.9,"GOOD","VERY GOOD")))) -> #DIV/0! | EH32: =IF(DO32<=2,"VERY POOR",IF(DO32<=6.5,"POOR",IF(DO32<=8,"NEED TO DEVELOP",IF(DO32<=8.9,"GOOD","VERY GOOD")))) -> NEED TO DEVELOP
B33: KM. ARMADA PERMATA | H33: 20180080 | I33: ANDRIK SISWANTO | J33: JURU MINYAK | L33: 0 tahun 2 bulan 17 hari | AN33: =AVERAGE(M33:AM33) -> #DIV/0! | CF33: =AVERAGE(BE33:CE33) -> #DIV/0! | CV33: 7.8 | CW33: 7.8 | CX33: 7.8 | CY33: 7.8 | CZ33: 7.8 | DA33: 7.8 | DB33: 7.8 | DC33: 7.8 | DD33: 7.8 | DI33: 7.8 | DJ33: 7.8 | DK33: 7.8 | DL33: 7.8 | DM33: 7.8 | DN33: 7.8 | DO33: =AVERAGE(CN33:DN33) -> 7.8 | DQ33: 1 | DT33: 1 | DW33: 1 | DZ33: 1 | EB33: 1 | EF33: =IF(AN33<=2,"VERY POOR",IF(AN33<=6.5,"POOR",IF(AN33<=8,"NEED TO DEVELOP",IF(AN33<=8.9,"GOOD","VERY GOOD")))) -> #DIV/0! | EG33: =IF(CF33<=2,"VERY POOR",IF(CF33<=6.5,"POOR",IF(CF33<=8,"NEED TO DEVELOP",IF(CF33<=8.9,"GOOD","VERY GOOD")))) -> #DIV/0! | EH33: =IF(DO33<=2,"VERY POOR",IF(DO33<=6.5,"POOR",IF(DO33<=8,"NEED TO DEVELOP",IF(DO33<=8.9,"GOOD","VERY GOOD")))) -> NEED TO DEVELOP
B34: KM. ARMADA PERMATA | H34: 20240078 | I34: PARIS | J34: JURU MINYAK | L34: 0 tahun 3 bulan 21 hari | AN34: =AVERAGE(M34:AM34) -> #DIV/0! | CF34: =AVERAGE(BE34:CE34) -> #DIV/0! | CV34: 7.9 | CW34: 7.9 | CX34: 7.9 | CY34: 7.9 | CZ34: 7.9 | DA34: 7.9 | DB34: 7.9 | DC34: 7.9 | DD34: 7.9 | DI34: 7.9 | DJ34: 7.9 | DK34: 7.9 | DL34: 7.9 | DM34: 7.9 | DN34: 7.9 | DO34: =AVERAGE(CN34:DN34) -> 7.9 | DQ34: 1 | DT34: 1 | DW34: 1 | DZ34: 1 | EB34: 1 | EF34: =IF(AN34<=2,"VERY POOR",IF(AN34<=6.5,"POOR",IF(AN34<=8,"NEED TO DEVELOP",IF(AN34<=8.9,"GOOD","VERY GOOD")))) -> #DIV/0! | EG34: =IF(CF34<=2,"VERY POOR",IF(CF34<=6.5,"POOR",IF(CF34<=8,"NEED TO DEVELOP",IF(CF34<=8.9,"GOOD","VERY GOOD")))) -> #DIV/0! | EH34: =IF(DO34<=2,"VERY POOR",IF(DO34<=6.5,"POOR",IF(DO34<=8,"NEED TO DEVELOP",IF(DO34<=8.9,"GOOD","VERY GOOD")))) -> NEED TO DEVELOP
B35: KM. ARMADA PERMATA | H35: 20230290 | I35: TRIKO LAKSONO | J35: JURU MINYAK | L35: 0 tahun 8 bulan 9 hari | AN35: =AVERAGE(M35:AM35) -> #DIV/0! | CF35: =AVERAGE(BE35:CE35) -> #DIV/0! | CV35: 7.6 | CW35: 7.6 | CX35: 7.6 | CY35: 7.6 | CZ35: 7.5 | DA35: 7.5 | DB35: 7.6 | DC35: 7.6 | DD35: 7.6 | DI35: 7.6 | DJ35: 7.6 | DK35: 7.6 | DL35: 7.6 | DM35: 7.6 | DN35: 7.6 | DO35: =AVERAGE(CN35:DN35) -> 7.5866667 | DQ35: 1 | DT35: 1 | DW35: 1 | DZ35: 1 | EB35: 1 | EF35: =IF(AN35<=2,"VERY POOR",IF(AN35<=6.5,"POOR",IF(AN35<=8,"NEED TO DEVELOP",IF(AN35<=8.9,"GOOD","VERY GOOD")))) -> #DIV/0! | EG35: =IF(CF35<=2,"VERY POOR",IF(CF35<=6.5,"POOR",IF(CF35<=8,"NEED TO DEVELOP",IF(CF35<=8.9,"GOOD","VERY GOOD")))) -> #DIV/0! | EH35: =IF(DO35<=2,"VERY POOR",IF(DO35<=6.5,"POOR",IF(DO35<=8,"NEED TO DEVELOP",IF(DO35<=8.9,"GOOD","VERY GOOD")))) -> NEED TO DEVELOP
B36: KM. ARMADA PERMATA | H36: 20090669 | I36: ENGLE RIANTO MANUAHE | J36: JURU MASAK I | L36: 0 tahun 8 bulan 22 hari | AN36: =AVERAGE(M36:AM36) -> #DIV/0! | CF36: =AVERAGE(BE36:CE36) -> #DIV/0! | CV36: 7 | CW36: 8 | CX36: 8 | CY36: 8 | CZ36: 8 | DA36: 7 | DB36: 8 | DC36: 8 | DD36: 8 | DF36: ` | DI36: 8 | DJ36: 8 | DK36: 8 | DL36: 8 | DM36: 7 | DN36: 8 | DO36: =AVERAGE(CN36:DN36) -> 7.8 | EF36: =IF(AN36<=2,"VERY POOR",IF(AN36<=6.5,"POOR",IF(AN36<=8,"NEED TO DEVELOP",IF(AN36<=8.9,"GOOD","VERY GOOD")))) -> #DIV/0! | EG36: =IF(CF36<=2,"VERY POOR",IF(CF36<=6.5,"POOR",IF(CF36<=8,"NEED TO DEVELOP",IF(CF36<=8.9,"GOOD","VERY GOOD")))) -> #DIV/0! | EH36: =IF(DO36<=2,"VERY POOR",IF(DO36<=6.5,"POOR",IF(DO36<=8,"NEED TO DEVELOP",IF(DO36<=8.9,"GOOD","VERY GOOD")))) -> NEED TO DEVELOP
